Workbook

Sheet Read Me
A1: Volt Library Catalogue
A2: Master data for the Volt Library directory app. Researched and checked as of October 29, 2026.
A4: At a glance
A5: Resources | B5: =COUNTA(Resources!A:A)-1 -> 353
A6: Sections | B6: =COUNTA(Sections!A:A)-1 -> 13
A7: Links verified | B7: =COUNTIF(Resources!S:S,"Verified")+COUNTIF(Resources!S:S,"Found in search") -> 351
A8: Links that need a check | B8: =COUNTIF(Resources!S:S,"Needs check") -> 2
A9: Kept from the Notion library | B9: =COUNTIF(Resources!R:R,"Notion import") -> 42
A10: Removed entries (see Removed tab) | B10: =COUNTA(Removed!A:A)-1 -> 51
A12: How to use it
A13: Resources tab | B13: One row per resource. This is the tab the app reads. Filter by Section, Topics, Status or Link Check.
A14: Adding a resource | B14: Add a row at the bottom. Use the next ID for its section (e.g. LAW-036), pick Section from the dropdown, and fill at least Name, Topics, Description and URL.
A15: Editing | B15: Edit any cell directly. When you re-check a link or a date, set Link Check and update Last Checked.
A16: Grey rows | B16: An event whose End Date has passed turns grey automatically. Remove it or replace it with the next edition.
A17: Amber cells | B17: Link Check = Needs check. The URL is the official address as far as known but was not opened during research. Check these before launch.
A18: Sections tab | B18: The app's section list: key, code, display name and description, with live counts.
A19: Coverage tab | B19: Counts by section and topic, to spot gaps (for example, few AI entries in a section).
A20: Removed tab | B20: Entries dropped from the library, and why.
A22: Columns
A23: ID | B23: Section code + number. Stable; never reuse an ID.
A24: Name | B24: Display name in the app.
A25: Section / Section Key | B25: Display name and the key the app uses (laws, regulators, frameworks, certifications, learning, events, research, news, podcasts, books, tools, communities, jobs).
A26: Type | B26: What kind of resource it is (Law, Framework, Certification, Podcast, Job board...). Shown as the small label under the name.
A27: Topics | B27: Semicolon-separated, from: Cybersecurity; Privacy; AI; Tech Law; General.
A28: Description | B28: One plain sentence, 160 characters or fewer.
A29: URL | B29: Official page. No affiliate links.
A30: Publisher | B30: Issuing body, organizer, host or author's publisher.
A31: Jurisdiction | B31: Where it applies or is based: Global, EU, UK, US, US-CA, Nigeria, etc.
A32: Level | B32: Beginner, Intermediate, Advanced or All (learning, certifications, books, events).
A33: Cost | B33: Free, Freemium, Paid, or a price note. Prices are as of the Last Checked date.
A34: Format | B34: Online, In person, Hybrid, Audio, Print/ebook, Exam, Download, Software.
... A41: Curator Notes | B41: Key dates, versions, fees, prerequisites and what to watch. Not shown in the app.
A43: Updating the app
A44: Data | B44: Each Resources row becomes one entry in the app's DATA list: Name, Section Key, Type, Topics (as codes c, p, a, l, g), URL, and for events {when, end, loc, cost} from Start/End Date, Location and Cost.
A45: Sections | B45: The app currently has 7 sections; this catalogue has 13. Replace the app's CATS list with the Sections tab (key, code, name, description).
A46: New topic | B46: Tech Law (code l) is new. Add it to the app's TOPICS list and give it a colour.
A47: Descriptions | B47: The app does not show descriptions yet. Add one line under each name using the Description column.

Sheet Resources
A1: ID | B1: Name | C1: Section | D1: Section Key | E1: Type | F1: Topics | G1: Description | H1: URL | I1: Publisher | J1: Jurisdiction | K1: Level | L1: Cost | M1: Format | N1: Start Date | O1: End Date | P1: Location | Q1: Status | R1: Origin | S1: Link Check | T1: Last Checked | U1: Curator Notes
A2: LAW-001 | B2: General Data Protection Regulation (Regulation (EU) 2016/679) | C2: Laws & Regulations | D2: laws | E2: Regulation | F2: Privacy | G2: EU regulation setting rules for processing personal data, data subject rights, controller and processor duties, transfers and fines. | H2: https://eur-lex.europa.eu/eli/reg/2016/679/oj/eng | I2: European Parliament and Council of the EU | J2: EU | L2: Free | M2: Online | N2: 43245 | Q2: In force | R2: New | S2: Verified | T2: 46324 | U2: Applies since May 25, 2018. Digital Omnibus proposal (COM(2025) 837) would amend GDPR and move cookie rules into it; no Council mandate or trilogue as of mid-Oct 2026. Watch for end-2026 deal push.
A3: LAW-002 | B3: EU Artificial Intelligence Act (Regulation (EU) 2024/1689) | C3: Laws & Regulations | D3: laws | E3: Regulation | F3: AI | G3: Risk-based EU rules for AI systems and general-purpose AI models: prohibited practices, high-risk requirements, transparency and governance. | H3: https://eur-lex.europa.eu/eli/reg/2024/1689/oj/eng | I3: European Parliament and Council of the EU | J3: EU | L3: Free | M3: Online | Q3: Partly in force | R3: New | S3: Verified | T3: 46324 | U3: In force Aug 1, 2024. Bans and AI literacy Feb 2, 2025; GPAI Aug 2, 2025; Art. 50 transparency Aug 2, 2026. AI Omnibus Reg. (EU) 2026/1744 (in force Jul 27, 2026) moved Annex III high-risk to Dec 2, 2027 and Annex I to Aug 2, 2028.
A4: LAW-003 | B4: NIS2 Directive (Directive (EU) 2022/2555) | C4: Laws & Regulations | D4: laws | E4: Directive | F4: Cybersecurity | G4: EU directive requiring essential and important entities in critical sectors to manage cybersecurity risk and report significant incidents. | H4: https://eur-lex.europa.eu/eli/dir/2022/2555/oj/eng | I4: European Parliament and Council of the EU | J4: EU | L4: Free | M4: Online | N4: 45583 | Q4: In force | R4: New | S4: Verified | T4: 46324 | U4: Transposition deadline Oct 17, 2024; national measures apply from Oct 18, 2024. Obligations arise through national laws, so check each Member State's transposition. 24-hour early warning and 72-hour incident notification.
A5: LAW-004 | B5: Digital Operational Resilience Act (DORA) (Regulation (EU) 2022/2554) | C5: Laws & Regulations | D5: laws | E5: Regulation | F5: Cybersecurity | G5: EU regulation on ICT risk management, incident reporting, resilience testing and third-party ICT risk for financial entities. | H5: https://eur-lex.europa.eu/eli/reg/2022/2554/oj/eng | I5: European Parliament and Council of the EU | J5: EU | L5: Free | M5: Online | N5: 45674 | Q5: In force | R5: New | S5: Verified | T5: 46324 | U5: Applies from Jan 17, 2025, with supporting RTS/ITS technical standards. Includes an oversight framework for critical ICT third-party service providers run by the European Supervisory Authorities.
A6: LAW-005 | B6: Cyber Resilience Act (Regulation (EU) 2024/2847) | C6: Laws & Regulations | D6: laws | E6: Regulation | F6: Cybersecurity | G6: EU regulation setting cybersecurity requirements for hardware and software products with digital elements across their lifecycle. | H6: https://eur-lex.europa.eu/eli/reg/2024/2847/oj/eng | I6: European Parliament and Council of the EU | J6: EU | L6: Free | M6: Online | Q6: Partly in force | R6: New | S6: Verified | T6: 46324 | U6: In force Dec 10, 2024. Manufacturer reporting of actively exploited vulnerabilities and severe incidents applies from Sep 11, 2026 (to CSIRTs and ENISA). Most obligations apply from Dec 11, 2027.
A7: LAW-006 | B7: EU Data Act (Regulation (EU) 2023/2854) | C7: Laws & Regulations | D7: laws | E7: Regulation | F7: Tech Law; Privacy | G7: EU regulation on access to and use of data from connected products and related services, B2B data sharing terms and cloud switching. | H7: https://eur-lex.europa.eu/eli/reg/2023/2854/oj/eng | I7: European Parliament and Council of the EU | J7: EU | L7: Free | M7: Online | N7: 45912 | Q7: In force | R7: New | S7: Verified | T7: 46324 | U7: Applies from Sep 12, 2025. Access-by-design duties for products placed on market after Sep 12, 2026. Unfair-terms rules reach older contracts from Sep 12, 2027. Digital Omnibus proposes amendments (pending).
A8: LAW-007 | B8: ePrivacy Directive (Directive 2002/58/EC) | C8: Laws & Regulations | D8: laws | E8: Directive | F8: Privacy | G8: EU directive on privacy in electronic communications, covering confidentiality, cookies and similar tracking, traffic data and direct marketing. | H8: https://eur-lex.europa.eu/eli/dir/2002/58/oj/eng | I8: European Parliament and Council of the EU | J8: EU | L8: Free | M8: Online | Q8: In force | R8: New | S8: Verified | T8: 46324 | U8: Amended 2009 (cookie consent). Applied through national laws. The proposed ePrivacy Regulation was withdrawn in 2025; the pending Digital Omnibus would move cookie/terminal-device rules into the GDPR.
A9: LAW-008 | B9: UK GDPR and Data Protection Act 2018 | C9: Laws & Regulations | D9: laws | E9: Law | F9: Privacy | G9: UK framework for personal data processing: the Act supplements the retained UK GDPR and covers law enforcement and intelligence processing. | H9: https://www.legislation.gov.uk/ukpga/2018/12/contents | I9: UK Parliament | J9: UK | L9: Free | M9: Online | N9: 43245 | Q9: In force | R9: New | S9: Verified | T9: 46324 | U9: UK GDPR is the retained version of EU GDPR. Both were substantially amended by the Data (Use and Access) Act 2025, with main changes in force from Feb 5, 2026.
A10: LAW-009 | B10: Data (Use and Access) Act 2025 | C10: Laws & Regulations | D10: laws | E10: Law | F10: Privacy; Tech Law | G10: UK Act amending UK GDPR, DPA 2018 and PECR, creating smart data and digital verification regimes, and restructuring the ICO. | H10: https://www.legislation.gov.uk/ukpga/2025/18/contents | I10: UK Parliament | J10: UK | L10: Free | M10: Online | Q10: Partly in force | R10: New | S10: Verified | T10: 46324 | U10: Royal Assent Jun 19, 2025. Main data protection changes in force Feb 5, 2026 (Commencement No. 6). Complaints-handling duty from Jun 19, 2026. ICO became the Information Commission on Sep 30, 2026. Some provisions still commencing.
A11: LAW-010 | B11: HIPAA Privacy, Security and Breach Notification Rules (45 CFR Parts 160 and 164) | C11: Laws & Regulations | D11: laws | E11: Regulation | F11: Privacy; Cybersecurity | G11: US federal rules governing use, disclosure and security of protected health information by covered entities and business associates. | H11: https://www.ecfr.gov/current/title-45/subtitle-A/subchapter-C/part-164 | I11: U.S. Department of Health and Human Services | J11: US | L11: Free | M11: Online | Q11: In force | R11: New | S11: Verified | T11: 46324 | U11: Enforced by HHS OCR. Proposed Security Rule overhaul (NPRM Jan 2025: MFA, encryption, asset inventory) has not been finalized; HHS has signalled final action in 2027.
A12: LAW-011 | B12: GLBA Safeguards Rule (16 CFR Part 314) | C12: Laws & Regulations | D12: laws | E12: Regulation | F12: Cybersecurity; Privacy | G12: FTC rule under the Gramm-Leach-Bliley Act requiring non-bank financial institutions to run an information security program. | H12: https://www.ecfr.gov/current/title-16/chapter-I/subchapter-C/part-314 | I12: Federal Trade Commission | J12: US | L12: Free | M12: Online | Q12: In force | R12: New | S12: Verified | T12: 46324 | U12: Amended 2021 (specific program elements, compliance from Jun 9, 2023). Breach notice to FTC for events affecting 500+ consumers effective May 13, 2024 (16 CFR 314.4(j)).
A13: LAW-012 | B13: Children's Online Privacy Protection Rule (COPPA Rule) (16 CFR Part 312) | C13: Laws & Regulations | D13: laws | E13: Regulation | F13: Privacy | G13: FTC rule requiring verifiable parental consent and data limits for online services directed to, or knowingly collecting data from, children under 13. | H13: https://www.ecfr.gov/current/title-16/chapter-I/subchapter-C/part-312 | I13: Federal Trade Commission | J13: US | L13: Free | M13: Online | Q13: In force | R13: New | S13: Verified | T13: 46324 | U13: Amended rule published Apr 22, 2025 (90 FR 16977), effective Jun 23, 2025; compliance required by Apr 22, 2026. Adds separate consent for third-party disclosures, data retention limits and a written security program.
A14: LAW-013 | B14: FERPA Regulations (34 CFR Part 99) | C14: Laws & Regulations | D14: laws | E14: Regulation | F14: Privacy | G14: US Department of Education rules on the privacy of student education records, parental and student access rights, and disclosure limits. | H14: https://www.ecfr.gov/current/title-34/subtitle-A/part-99 | I14: U.S. Department of Education | J14: US | L14: Free | M14: Online | Q14: In force | R14: New | S14: Found in search | T14: 46324 | U14: Implements the Family Educational Rights and Privacy Act (1974). Applies to schools receiving federal education funds; relevant to edtech vendors acting as school officials.
A15: LAW-014 | B15: SEC Cybersecurity Risk Management, Strategy, Governance, and Incident Disclosure Rules (Release 33-11216) | C15: Laws & Regulations | D15: laws | E15: Rules | F15: Cybersecurity | G15: SEC rules requiring public companies to disclose material cybersecurity incidents on Form 8-K and describe cyber risk governance annually. | H15: https://www.sec.gov/rules-regulations/2023/07/s7-09-22 | I15: U.S. Securities and Exchange Commission | J15: US | L15: Free | M15: Online | N15: 45174 | Q15: In force | R15: New | S15: Verified | T15: 46324 | U15: Adopted Jul 26, 2023; effective Sep 5, 2023. Form 8-K Item 1.05 due 4 business days after materiality determination; Reg S-K Item 106 annual disclosure. Banking and securities groups petitioned in 2025-26 to rescind or narrow.
A16: LAW-015 | B16: Cyber Incident Reporting for Critical Infrastructure Act of 2022 (CIRCIA) | C16: Laws & Regulations | D16: laws | E16: Law | F16: Cybersecurity | G16: US law directing CISA to require critical infrastructure entities to report covered cyber incidents and ransom payments. | H16: https://www.cisa.gov/topics/cyber-threats-and-advisories/information-sharing/cyber-incident-reporting-critical-infrastructure-act-2022-circia | I16: Cybersecurity and Infrastructure Security Agency (CISA) | J16: US | L16: Free | M16: Online | Q16: Partly in force | R16: New | S16: Verified | T16: 46324 | U16: Enacted Mar 15, 2022; NPRM Apr 4, 2024. Final rule sent to White House (OIRA) review by early Oct 2026; publication expected late 2026. Mandatory 72-hour incident / 24-hour ransom payment reporting starts only once the final rule takes effect.
A17: LAW-016 | B17: FTC Act Section 5 (15 U.S.C. 45) | C17: Laws & Regulations | D17: laws | E17: Law | F17: Privacy; Cybersecurity; AI | G17: US statute prohibiting unfair or deceptive acts or practices; the FTC's main legal basis for privacy, data security and AI enforcement. | H17: https://www.govinfo.gov/link/uscode/15/45 | I17: U.S. Congress | J17: US | L17: Free | M17: Online | Q17: In force | R17: New | S17: Verified | T17: 46324 | U17: Basis for FTC consent orders on data security, privacy misrepresentations and deceptive AI claims. Remedies often include algorithm/data deletion and multi-year security program requirements.
A18: LAW-017 | B18: California Consumer Privacy Act (CCPA), as amended by the CPRA (Cal. Civ. Code 1798.100 et seq.) | C18: Laws & Regulations | D18: laws | E18: Law | F18: Privacy | G18: California statute giving consumers rights to know, delete, correct and opt out of sale or sharing of personal information. | H18: https://leginfo.legislature.ca.gov/faces/codes_displayText.xhtml?division=3.&lawCode=CIV&part=4.&title=1.81.5 | I18: California Legislature | J18: US-CA | L18: Free | M18: Online | N18: 43831 | Q18: In force | R18: New | S18: Found in search | T18: 46324 | U18: Effective Jan 1, 2020; CPRA amendments operative Jan 1, 2023. Enforced by CalPrivacy (California Privacy Protection Agency) and the California Attorney General.
A19: LAW-018 | B19: CCPA Regulations on ADMT, Risk Assessments and Cybersecurity Audits (Cal. Code Regs. tit. 11, § 7000 et seq.) | C19: Laws & Regulations | D19: laws | E19: Rules | F19: Privacy; AI; Cybersecurity | G19: CalPrivacy regulations adding automated decisionmaking technology rights, privacy risk assessments and annual cybersecurity audits to the CCPA rules. | H19: https://cppa.ca.gov/regulations/ccpa_updates.html | I19: California Privacy Protection Agency (CalPrivacy) | J19: US-CA | L19: Free | M19: Online | N19: 46023 | Q19: Partly in force | R19: New | S19: Verified | T19: 46324 | U19: Approved by OAL Sep 22, 2025; effective Jan 1, 2026. ADMT compliance from Jan 1, 2027. Risk assessment attestations due Apr 1, 2028. Cybersecurity audit certifications due Apr 1, 2028/2029/2030 by revenue tier.
A20: LAW-019 | B20: Colorado AI Act (SB 24-205), repealed and reenacted by SB 26-189 (Automated Decision-Making Technology) | C20: Laws & Regulations | D20: laws | E20: Law | F20: AI | G20: Colorado law regulating automated decision-making technology used in consequential decisions such as employment, housing, lending and insurance. | H20: https://leg.colorado.gov/bills/sb26-189 | I20: Colorado General Assembly | J20: US-CO | L20: Free | M20: Online | N20: 46388 | Q20: Enacted - not yet in force | R20: New | S20: Verified | T20: 46324 | U20: SB 24-205 (2024) was delayed to Jun 30, 2026, then rewritten by SB 26-189, signed May 14, 2026: now an ADMT notice, explanation, correction and human-review law effective Jan 1, 2027. AG-only enforcement; 60-day cure.
A21: LAW-020 | B21: Texas Responsible Artificial Intelligence Governance Act (TRAIGA) (HB 149) | C21: Laws & Regulations | D21: laws | E21: Law | F21: AI | G21: Texas law banning certain intentional harmful AI uses, setting disclosure duties for government and health AI uses, and creating an AI sandbox. | H21: https://capitol.texas.gov/tlodocs/89R/billtext/html/HB00149F.htm | I21: Texas Legislature | J21: US-TX | L21: Free | M21: Online | N21: 46023 | Q21: In force | R21: New | S21: Verified | T21: 46324 | U21: Effective Jan 1, 2026 (Bus. & Com. Code ch. 551-554). Attorney General has exclusive enforcement; 60-day cure; penalties up to $200,000 per uncurable violation. Creates 36-month regulatory sandbox and Texas AI Council.
A22: LAW-021 | B22: Texas Data Privacy and Security Act (TDPSA) (HB 4) | C22: Laws & Regulations | D22: laws | E22: Law | F22: Privacy | G22: Texas consumer privacy law granting access, deletion, correction and opt-out rights and requiring data protection assessments. | H22: https://capitol.texas.gov/tlodocs/88R/billtext/html/HB00004F.htm | I22: Texas Legislature | J22: US-TX | L22: Free | M22: Online | N22: 45474 | Q22: In force | R22: New | S22: Verified | T22: 46324 | U22: Effective Jul 1, 2024 (Bus. & Com. Code ch. 541); universal opt-out signal duty from Jan 1, 2025. Applies to most businesses regardless of revenue (small-business carve-out). Attorney General enforces; 30-day cure.
A23: LAW-022 | B23: Virginia Consumer Data Protection Act (VCDPA) (Va. Code 59.1-575 et seq.) | C23: Laws & Regulations | D23: laws | E23: Law | F23: Privacy | G23: Virginia consumer privacy law with access, deletion, correction and opt-out rights, sensitive-data consent and data protection assessments. | H23: https://law.lis.virginia.gov/vacodefull/title59.1/chapter53/ | I23: Virginia General Assembly | J23: US-VA | L23: Free | M23: Online | N23: 44927 | Q23: In force | R23: New | S23: Verified | T23: 46324 | U23: Effective Jan 1, 2023; template for many later state privacy laws. AG enforcement with 30-day cure period. Amended since, incl. added protections for children's data and a 2025 section (59.1-577.1) limiting social media use by minors under 16.
A24: LAW-023 | B24: Illinois Biometric Information Privacy Act (BIPA) (740 ILCS 14) | C24: Laws & Regulations | D24: laws | E24: Law | F24: Privacy | G24: Illinois law requiring notice, written consent and retention policies for biometric identifiers, with a private right of action. | H24: https://www.ilga.gov/legislation/ilcs/ilcs3.asp?ActID=3004&ChapterID=57 | I24: Illinois General Assembly | J24: US-IL | L24: Free | M24: Online | N24: 39724 | Q24: In force | R24: New | S24: Found in search | T24: 46324 | U24: Private right of action: $1,000 negligent / $5,000 intentional or reckless per violation. SB 2979 (Aug 2, 2024) limits recovery to one violation per person per collection method and allows electronic consent.
A25: LAW-024 | B25: NYC Local Law 144 of 2021 (Automated Employment Decision Tools) | C25: Laws & Regulations | D25: laws | E25: Law | F25: AI | G25: New York City law requiring annual bias audits, public audit summaries and candidate notices before employers use automated employment decision tools. | H25: https://www.nyc.gov/site/dca/about/automated-employment-decision-tools.page | I25: New York City Council; Department of Consumer and Worker Protection | J25: US-NY | L25: Free | M25: Online | N25: 45112 | Q25: In force | R25: New | S25: Verified | T25: 46324 | U25: DCWP enforcement began Jul 5, 2023 under implementing rules (6 RCNY 5-300 et seq.). Applies to tools that substantially assist hiring or promotion decisions for NYC jobs.
A26: LAW-025 | B26: NYDFS Cybersecurity Regulation (23 NYCRR Part 500) | C26: Laws & Regulations | D26: laws | E26: Regulation | F26: Cybersecurity | G26: New York DFS rule requiring regulated financial entities to maintain cybersecurity programs, CISO oversight, MFA and 72-hour incident notice. | H26: https://www.dfs.ny.gov/cybersecurity | I26: New York State Department of Financial Services | J26: US-NY | L26: Free | M26: Online | Q26: In force | R26: New | S26: Verified | T26: 46324 | U26: Original rule effective Mar 1, 2017. Second Amendment (Nov 1, 2023) phased in; final requirements (universal MFA, asset inventory) effective Nov 1, 2025. Annual compliance certification due Apr 15.
A27: LAW-026 | B27: Nigeria Data Protection Act 2023 | C27: Laws & Regulations | D27: laws | E27: Law | F27: Privacy | G27: Nigerian statute governing personal data processing, data subject rights, cross-border transfers, and establishing the Nigeria Data Protection Commission. | H27: https://ndpc.gov.ng/wp-content/uploads/2024/03/Nigeria_Data_Protection_Act_2023.pdf | I27: National Assembly of Nigeria | J27: Nigeria | L27: Free | M27: Online | Q27: In force | R27: New | S27: Verified | T27: 46324 | U27: Signed June 12, 2023 (Act No. 37). Replaced the NDPR 2019 regime as primary law; operationalized by the GAID 2025. Data controllers/processors of major importance must register with the NDPC. URL is the official Act text (Gazette reproduction) on ndpc.gov.ng.
A28: LAW-027 | B28: NDPC General Application and Implementation Directive (GAID) 2025 | C28: Laws & Regulations | D28: laws | E28: Rules | F28: Privacy; AI | G28: NDPC directive implementing the Nigeria Data Protection Act 2023, covering compliance audits, DPOs, DPIAs, legitimate interest and emerging tech. | H28: https://ndpc.gov.ng/wp-content/uploads/2025/07/NDP-ACT-GAID-2025-MARCH-20TH.pdf | I28: Nigeria Data Protection Commission (NDPC) | J28: Nigeria | L28: Free | M28: Online | N28: 45919 | Q28: In force | R28: New | S28: Verified | T28: 46324 | U28: Issued Mar 20, 2025; effective Sep 19, 2025. Replaces the NDPR 2019 and its 2020 Implementation Framework. Sets Compliance Audit Return filing and fees, DPO credentials, DPIA template, and rules for AI, blockchain and IoT processing.
A29: LAW-028 | B29: Protection of Personal Information Act 4 of 2013 (POPIA) | C29: Laws & Regulations | D29: laws | E29: Law | F29: Privacy | G29: South African law setting conditions for lawful processing of personal information, data subject rights, breach notification and direct marketing limits. | H29: https://www.gov.za/sites/default/files/gcis_document/201409/3706726-11act4of2013protectionofpersonalinforcorrect.pdf | I29: Parliament of South Africa | J29: South Africa | L29: Free | M29: Online | N29: 44378 | Q29: In force | R29: New | S29: Verified | T29: 46324 | U29: Main provisions commenced Jul 1, 2020 with a one-year grace period; compliance required from Jul 1, 2021. Enforced by the Information Regulator, which also oversees PAIA.
A30: LAW-029 | B30: Kenya Data Protection Act, 2019 (No. 24 of 2019) | C30: Laws & Regulations | D30: laws | E30: Law | F30: Privacy | G30: Kenyan statute regulating personal data processing, data subject rights, controller and processor registration, and the Data Commissioner's powers. | H30: https://new.kenyalaw.org/akn/ke/act/2019/24/eng@2022-12-31 | I30: Parliament of Kenya | J30: Kenya | L30: Free | M30: Online | N30: 43794 | Q30: In force | R30: New | S30: Verified | T30: 46324 | U30: Commenced Nov 25, 2019. Supplemented by the Data Protection (General) Regulations 2021 and registration and complaints regulations. URL is the official Kenya Law consolidated text (version dated 2022-12-31).
A31: LAW-030 | B31: Brazil General Data Protection Law (LGPD) (Law No. 13,709/2018) | C31: Laws & Regulations | D31: laws | E31: Law | F31: Privacy | G31: Brazilian law governing personal data processing, legal bases, data subject rights and international transfers, enforced by the ANPD. | H31: https://www.planalto.gov.br/ccivil_03/_ato2015-2018/2018/lei/l13709compilado.htm | I31: National Congress of Brazil | J31: Brazil | L31: Free | M31: Online | N31: 44092 | Q31: In force | R31: New | S31: Verified | T31: 46324 | U31: In force Sep 18, 2020; administrative sanctions applicable from Aug 1, 2021. ANPD has issued regulations on sanctions, international transfers (SCCs) and DPOs.
A32: LAW-031 | B32: India Digital Personal Data Protection Act, 2023 and DPDP Rules, 2025 | C32: Laws & Regulations | D32: laws | E32: Law | F32: Privacy | G32: Indian law and implementing rules governing digital personal data processing, consent, data principal rights and the Data Protection Board. | H32: https://www.meity.gov.in/static/uploads/2024/06/2bf1f0e9f04e6fb4f8fef35e82c42aa5.pdf | I32: Ministry of Electronics and Information Technology (MeitY) | J32: India | L32: Free | M32: Online | Q32: Partly in force | R32: New | S32: Verified | T32: 46324 | U32: Act assented Aug 11, 2023. Rules notified Nov 13, 2025 (G.S.R. 846(E)) with staged commencement: Board provisions Nov 13, 2025; consent manager provisions Nov 13, 2026; remaining obligations May 13, 2027. URL is the official Act text on meity.gov.in.
A33: LAW-032 | B33: Personal Information Protection and Electronic Documents Act (PIPEDA) (S.C. 2000, c. 5) | C33: Laws & Regulations | D33: laws | E33: Law | F33: Privacy | G33: Canadian federal law governing how private-sector organizations collect, use and disclose personal information in commercial activity. | H33: https://laws-lois.justice.gc.ca/eng/acts/P-8.6/ | I33: Parliament of Canada | J33: Canada | L33: Free | M33: Online | Q33: In force | R33: New | S33: Verified | T33: 46324 | U33: Mandatory breach reporting since Nov 1, 2018. Bill C-27 (CPPA and AIDA) died on prorogation in Jan 2025; watch for reintroduced federal privacy reform. Quebec Law 25 and other provincial laws apply in parallel.
A34: LAW-033 | B34: Singapore Personal Data Protection Act 2012 (PDPA) | C34: Laws & Regulations | D34: laws | E34: Law | F34: Privacy | G34: Singapore law governing private-sector collection, use and disclosure of personal data, including consent, breach notification and Do Not Call rules. | H34: https://sso.agc.gov.sg/Act/PDPA2012 | I34: Parliament of Singapore | J34: Singapore | L34: Free | M34: Online | Q34: In force | R34: New | S34: Found in search | T34: 46324 | U34: Main obligations in force since Jul 2, 2014. 2020 amendments added mandatory breach notification (Feb 1, 2021) and fines up to 10% of Singapore turnover (Oct 1, 2022). Administered by the PDPC.
A35: LAW-034 | B35: Japan Act on the Protection of Personal Information (APPI) | C35: Laws & Regulations | D35: laws | E35: Law | F35: Privacy | G35: Japanese law on business handling of personal information, including purpose limits, third-party provision, cross-border transfers and breach reports. | H35: https://www.ppc.go.jp/en/ | I35: National Diet of Japan; Personal Information Protection Commission | J35: Japan | L35: Free | M35: Online | Q35: In force | R35: New | S35: Verified | T35: 46324 | U35: Enacted 2003; major 2020 amendments in force Apr 1, 2022 (breach reporting, pseudonymized data). PPC adopted a System Reform Policy under the triennial review on Jan 9, 2026; check PPC for amendment bill status. URL is PPC English site with English translations of the Act.
A36: LAW-035 | B36: Council of Europe Framework Convention on Artificial Intelligence and Human Rights, Democracy and the Rule of Law (CETS No. 225) | C36: Laws & Regulations | D36: laws | E36: Treaty | F36: AI | G36: First binding international treaty on AI, requiring parties to ensure AI lifecycle activities respect human rights, democracy and the rule of law. | H36: https://www.coe.int/en-GB/web/conventions/full-list2?module=signatures-by-treaty&treatynum=225 | I36: Council of Europe | J36: Council of Europe | L36: Free | M36: Online | Q36: Enacted - not yet in force | R36: New | S36: Verified | T36: 46324 | U36: Adopted May 17, 2024; opened for signature Sep 5, 2024 (signatories include the EU, UK, US, Canada, Japan). EU ratified May 15, 2026. Enters into force after five ratifications incl. three CoE member states; not yet in force as of Oct 2026.
A37: REG-001 | B37: Federal Trade Commission (FTC) | C37: Regulators & Official Guidance | D37: regulators | E37: Regulator | F37: Privacy; Cybersecurity; AI | G37: US federal agency enforcing consumer protection law on privacy, data security and AI claims, plus COPPA, the GLBA Safeguards Rule and related rules. | H37: https://www.ftc.gov/ | I37: Federal Trade Commission | J37: US | L37: Free | M37: Online | Q37: Active | R37: New | S37: Found in search | T37: 46324 | U37: Publishes enforcement actions, business guidance and policy statements. Key tools: FTC Act Section 5, COPPA Rule, Safeguards Rule, Health Breach Notification Rule.
A38: REG-002 | B38: California Privacy Protection Agency (CalPrivacy) | C38: Regulators & Official Guidance | D38: regulators | E38: Regulator | F38: Privacy; AI | G38: California agency that issues CCPA regulations, enforces the CCPA and runs the data broker registry and Delete Request and Opt-out Platform (DROP). | H38: https://privacy.ca.gov/about-us/about-calprivacy/ | I38: California Privacy Protection Agency | J38: US-CA | L38: Free | M38: Online | Q38: Active | R38: New | S38: Verified | T38: 46324 | U38: Now branded CalPrivacy and uses privacy.ca.gov (cppa.ca.gov still hosts regulations). DROP launched Jan 1, 2026; brokers must process DROP deletions from Aug 1, 2026. ADMT/risk/audit rules effective Jan 1, 2026.
A39: REG-003 | B39: HHS Office for Civil Rights (OCR) - HIPAA | C39: Regulators & Official Guidance | D39: regulators | E39: Regulator | F39: Privacy; Cybersecurity | G39: US HHS office that enforces the HIPAA Privacy, Security and Breach Notification Rules and publishes guidance and enforcement actions. | H39: https://www.hhs.gov/hipaa/index.html | I39: U.S. Department of Health and Human Services | J39: US | L39: Free | M39: Online | Q39: Active | R39: New | S39: Verified | T39: 46324 | U39: Runs the breach portal for incidents affecting 500+ individuals and a risk analysis enforcement initiative. Security Rule update proposed Jan 2025; final action now signalled for 2027.
A40: REG-004 | B40: U.S. Securities and Exchange Commission (SEC) | C40: Regulators & Official Guidance | D40: regulators | E40: Regulator | F40: Cybersecurity | G40: US securities regulator overseeing public company cybersecurity disclosure, Regulation S-P customer data safeguards and cyber-related enforcement. | H40: https://www.sec.gov/ | I40: U.S. Securities and Exchange Commission | J40: US | L40: Free | M40: Online | Q40: Active | R40: New | S40: Verified | T40: 46324 | U40: Cyber and Emerging Technologies Unit (CETU) created Feb 2025. Amended Regulation S-P (incident response and customer notice) adopted 2024 with phased compliance. Rescission petitions on 2023 cyber disclosure rules pending.
...

Sheet Sections
A1: Section Key | B1: Code | C1: Display Name | D1: Description | E1: Resources | F1: Links to check | G1: Kept from Notion
A2: laws | B2: LAW | C2: Laws & Regulations | D2: Primary legal texts on privacy, cybersecurity and AI, with current status and key dates. | E2: =COUNTIF(Resources!$D:$D,A2) -> 35 | F2: =COUNTIFS(Resources!$D:$D,A2,Resources!$S:$S,"Needs check") -> 0 | G2: =COUNTIFS(Resources!$D:$D,A2,Resources!$R:$R,"Notion import") -> 0
A3: regulators | B3: REG | C3: Regulators & Official Guidance | D3: Authorities that enforce these laws and the guidance they publish. | E3: =COUNTIF(Resources!$D:$D,A3) -> 21 | F3: =COUNTIFS(Resources!$D:$D,A3,Resources!$S:$S,"Needs check") -> 0 | G3: =COUNTIFS(Resources!$D:$D,A3,Resources!$R:$R,"Notion import") -> 0
A4: frameworks | B4: FRM | C4: Frameworks & Standards | D4: Standards, control sets and principles used to build, assess and audit programs. | E4: =COUNTIF(Resources!$D:$D,A4) -> 30 | F4: =COUNTIFS(Resources!$D:$D,A4,Resources!$S:$S,"Needs check") -> 0 | G4: =COUNTIFS(Resources!$D:$D,A4,Resources!$R:$R,"Notion import") -> 0
A5: certifications | B5: CRT | C5: Certifications | D5: Professional credentials in privacy, security, AI governance and e-discovery, beginner to expert. | E5: =COUNTIF(Resources!$D:$D,A5) -> 30 | F5: =COUNTIFS(Resources!$D:$D,A5,Resources!$S:$S,"Needs check") -> 0 | G5: =COUNTIFS(Resources!$D:$D,A5,Resources!$R:$R,"Notion import") -> 0
A6: learning | B6: LRN | C6: Learning Center | D6: Courses, labs and training programs. Courses teach a subject; they are not certifications. | E6: =COUNTIF(Resources!$D:$D,A6) -> 31 | F6: =COUNTIFS(Resources!$D:$D,A6,Resources!$S:$S,"Needs check") -> 0 | G6: =COUNTIFS(Resources!$D:$D,A6,Resources!$R:$R,"Notion import") -> 14
A7: events | B7: EVT | C7: Events | D7: Conferences, summits and training events from November 2026 onward. | E7: =COUNTIF(Resources!$D:$D,A7) -> 39 | F7: =COUNTIFS(Resources!$D:$D,A7,Resources!$S:$S,"Needs check") -> 0 | G7: =COUNTIFS(Resources!$D:$D,A7,Resources!$R:$R,"Notion import") -> 4
A8: research | B8: RES | C8: Research & Trackers | D8: Law trackers, enforcement databases, annual reports and research libraries. | E8: =COUNTIF(Resources!$D:$D,A8) -> 27 | F8: =COUNTIFS(Resources!$D:$D,A8,Resources!$S:$S,"Needs check") -> 1 | G8: =COUNTIFS(Resources!$D:$D,A8,Resources!$R:$R,"Notion import") -> 3
A9: news | B9: NWS | C9: Newsletters & News | D9: News sites, newsletters and law-firm blogs that track developments. | E9: =COUNTIF(Resources!$D:$D,A9) -> 22 | F9: =COUNTIFS(Resources!$D:$D,A9,Resources!$S:$S,"Needs check") -> 1 | G9: =COUNTIFS(Resources!$D:$D,A9,Resources!$R:$R,"Notion import") -> 0
A10: podcasts | B10: POD | C10: Podcasts | D10: Shows on privacy, security, AI policy and tech law. | E10: =COUNTIF(Resources!$D:$D,A10) -> 20 | F10: =COUNTIFS(Resources!$D:$D,A10,Resources!$S:$S,"Needs check") -> 0 | G10: =COUNTIFS(Resources!$D:$D,A10,Resources!$R:$R,"Notion import") -> 8
A11: books | B11: BKS | C11: Books & Literature | D11: Foundational and current books and articles, checked against real publications. | E11: =COUNTIF(Resources!$D:$D,A11) -> 31 | F11: =COUNTIFS(Resources!$D:$D,A11,Resources!$S:$S,"Needs check") -> 0 | G11: =COUNTIFS(Resources!$D:$D,A11,Resources!$R:$R,"Notion import") -> 0
A12: tools | B12: TLS | C12: Tools & Templates | D12: Free or low-cost tools, templates and assessment kits practitioners use. | E12: =COUNTIF(Resources!$D:$D,A12) -> 25 | F12: =COUNTIFS(Resources!$D:$D,A12,Resources!$S:$S,"Needs check") -> 0 | G12: =COUNTIFS(Resources!$D:$D,A12,Resources!$R:$R,"Notion import") -> 0
A13: communities | B13: COM | C13: Communities & Associations | D13: Professional bodies, advocacy groups and communities to join. | E13: =COUNTIF(Resources!$D:$D,A13) -> 21 | F13: =COUNTIFS(Resources!$D:$D,A13,Resources!$S:$S,"Needs check") -> 0 | G13: =COUNTIFS(Resources!$D:$D,A13,Resources!$R:$R,"Notion import") -> 0
A14: jobs | B14: JOB | C14: Job Boards & Careers | D14: Where to find roles, plus salary and workforce data. | E14: =COUNTIF(Resources!$D:$D,A14) -> 21 | F14: =COUNTIFS(Resources!$D:$D,A14,Resources!$S:$S,"Needs check") -> 0 | G14: =COUNTIFS(Resources!$D:$D,A14,Resources!$R:$R,"Notion import") -> 13
C15: Total | E15: =SUM(E2:E14) -> 353 | F15: =SUM(F2:F14) -> 2 | G15: =SUM(G2:G14) -> 42

Sheet Coverage
A1: Resources by section and topic
A2: A resource can carry several topics, so rows add up to more than the section total.
A4: Section | B4: Cybersecurity | C4: Privacy | D4: AI | E4: Tech Law | F4: General | G4: Section total
A5: Laws & Regulations | B5: =COUNTIFS(Resources!$D:$D,"laws",Resources!$F:$F,"*Cybersecurity*") -> 10 | C5: =COUNTIFS(Resources!$D:$D,"laws",Resources!$F:$F,"*Privacy*") -> 24 | D5: =COUNTIFS(Resources!$D:$D,"laws",Resources!$F:$F,"*AI*") -> 8 | E5: =COUNTIFS(Resources!$D:$D,"laws",Resources!$F:$F,"*Tech Law*") -> 2 | F5: =COUNTIFS(Resources!$D:$D,"laws",Resources!$F:$F,"*General*") -> 0 | G5: =COUNTIF(Resources!$D:$D,"laws") -> 35
A6: Regulators & Official Guidance | B6: =COUNTIFS(Resources!$D:$D,"regulators",Resources!$F:$F,"*Cybersecurity*") -> 6 | C6: =COUNTIFS(Resources!$D:$D,"regulators",Resources!$F:$F,"*Privacy*") -> 15 | D6: =COUNTIFS(Resources!$D:$D,"regulators",Resources!$F:$F,"*AI*") -> 10 | E6: =COUNTIFS(Resources!$D:$D,"regulators",Resources!$F:$F,"*Tech Law*") -> 0 | F6: =COUNTIFS(Resources!$D:$D,"regulators",Resources!$F:$F,"*General*") -> 0 | G6: =COUNTIF(Resources!$D:$D,"regulators") -> 21
A7: Frameworks & Standards | B7: =COUNTIFS(Resources!$D:$D,"frameworks",Resources!$F:$F,"*Cybersecurity*") -> 17 | C7: =COUNTIFS(Resources!$D:$D,"frameworks",Resources!$F:$F,"*Privacy*") -> 9 | D7: =COUNTIFS(Resources!$D:$D,"frameworks",Resources!$F:$F,"*AI*") -> 11 | E7: =COUNTIFS(Resources!$D:$D,"frameworks",Resources!$F:$F,"*Tech Law*") -> 2 | F7: =COUNTIFS(Resources!$D:$D,"frameworks",Resources!$F:$F,"*General*") -> 2 | G7: =COUNTIF(Resources!$D:$D,"frameworks") -> 30
A8: Certifications | B8: =COUNTIFS(Resources!$D:$D,"certifications",Resources!$F:$F,"*Cybersecurity*") -> 20 | C8: =COUNTIFS(Resources!$D:$D,"certifications",Resources!$F:$F,"*Privacy*") -> 11 | D8: =COUNTIFS(Resources!$D:$D,"certifications",Resources!$F:$F,"*AI*") -> 5 | E8: =COUNTIFS(Resources!$D:$D,"certifications",Resources!$F:$F,"*Tech Law*") -> 8 | F8: =COUNTIFS(Resources!$D:$D,"certifications",Resources!$F:$F,"*General*") -> 0 | G8: =COUNTIF(Resources!$D:$D,"certifications") -> 30
A9: Learning Center | B9: =COUNTIFS(Resources!$D:$D,"learning",Resources!$F:$F,"*Cybersecurity*") -> 23 | C9: =COUNTIFS(Resources!$D:$D,"learning",Resources!$F:$F,"*Privacy*") -> 6 | D9: =COUNTIFS(Resources!$D:$D,"learning",Resources!$F:$F,"*AI*") -> 14 | E9: =COUNTIFS(Resources!$D:$D,"learning",Resources!$F:$F,"*Tech Law*") -> 2 | F9: =COUNTIFS(Resources!$D:$D,"learning",Resources!$F:$F,"*General*") -> 7 | G9: =COUNTIF(Resources!$D:$D,"learning") -> 31
A10: Events | B10: =COUNTIFS(Resources!$D:$D,"events",Resources!$F:$F,"*Cybersecurity*") -> 21 | C10: =COUNTIFS(Resources!$D:$D,"events",Resources!$F:$F,"*Privacy*") -> 18 | D10: =COUNTIFS(Resources!$D:$D,"events",Resources!$F:$F,"*AI*") -> 20 | E10: =COUNTIFS(Resources!$D:$D,"events",Resources!$F:$F,"*Tech Law*") -> 18 | F10: =COUNTIFS(Resources!$D:$D,"events",Resources!$F:$F,"*General*") -> 0 | G10: =COUNTIF(Resources!$D:$D,"events") -> 39
A11: Research & Trackers | B11: =COUNTIFS(Resources!$D:$D,"research",Resources!$F:$F,"*Cybersecurity*") -> 10 | C11: =COUNTIFS(Resources!$D:$D,"research",Resources!$F:$F,"*Privacy*") -> 9 | D11: =COUNTIFS(Resources!$D:$D,"research",Resources!$F:$F,"*AI*") -> 9 | E11: =COUNTIFS(Resources!$D:$D,"research",Resources!$F:$F,"*Tech Law*") -> 14 | F11: =COUNTIFS(Resources!$D:$D,"research",Resources!$F:$F,"*General*") -> 4 | G11: =COUNTIF(Resources!$D:$D,"research") -> 27
A12: Newsletters & News | B12: =COUNTIFS(Resources!$D:$D,"news",Resources!$F:$F,"*Cybersecurity*") -> 12 | C12: =COUNTIFS(Resources!$D:$D,"news",Resources!$F:$F,"*Privacy*") -> 10 | D12: =COUNTIFS(Resources!$D:$D,"news",Resources!$F:$F,"*AI*") -> 10 | E12: =COUNTIFS(Resources!$D:$D,"news",Resources!$F:$F,"*Tech Law*") -> 11 | F12: =COUNTIFS(Resources!$D:$D,"news",Resources!$F:$F,"*General*") -> 4 | G12: =COUNTIF(Resources!$D:$D,"news") -> 22
A13: Podcasts | B13: =COUNTIFS(Resources!$D:$D,"podcasts",Resources!$F:$F,"*Cybersecurity*") -> 10 | C13: =COUNTIFS(Resources!$D:$D,"podcasts",Resources!$F:$F,"*Privacy*") -> 10 | D13: =COUNTIFS(Resources!$D:$D,"podcasts",Resources!$F:$F,"*AI*") -> 11 | E13: =COUNTIFS(Resources!$D:$D,"podcasts",Resources!$F:$F,"*Tech Law*") -> 7 | F13: =COUNTIFS(Resources!$D:$D,"podcasts",Resources!$F:$F,"*General*") -> 4 | G13: =COUNTIF(Resources!$D:$D,"podcasts") -> 20
A14: Books & Literature | B14: =COUNTIFS(Resources!$D:$D,"books",Resources!$F:$F,"*Cybersecurity*") -> 10 | C14: =COUNTIFS(Resources!$D:$D,"books",Resources!$F:$F,"*Privacy*") -> 22 | D14: =COUNTIFS(Resources!$D:$D,"books",Resources!$F:$F,"*AI*") -> 8 | E14: =COUNTIFS(Resources!$D:$D,"books",Resources!$F:$F,"*Tech Law*") -> 17 | F14: =COUNTIFS(Resources!$D:$D,"books",Resources!$F:$F,"*General*") -> 0 | G14: =COUNTIF(Resources!$D:$D,"books") -> 31
A15: Tools & Templates | B15: =COUNTIFS(Resources!$D:$D,"tools",Resources!$F:$F,"*Cybersecurity*") -> 14 | C15: =COUNTIFS(Resources!$D:$D,"tools",Resources!$F:$F,"*Privacy*") -> 7 | D15: =COUNTIFS(Resources!$D:$D,"tools",Resources!$F:$F,"*AI*") -> 8 | E15: =COUNTIFS(Resources!$D:$D,"tools",Resources!$F:$F,"*Tech Law*") -> 1 | F15: =COUNTIFS(Resources!$D:$D,"tools",Resources!$F:$F,"*General*") -> 0 | G15: =COUNTIF(Resources!$D:$D,"tools") -> 25
A16: Communities & Associations | B16: =COUNTIFS(Resources!$D:$D,"communities",Resources!$F:$F,"*Cybersecurity*") -> 10 | C16: =COUNTIFS(Resources!$D:$D,"communities",Resources!$F:$F,"*Privacy*") -> 11 | D16: =COUNTIFS(Resources!$D:$D,"communities",Resources!$F:$F,"*AI*") -> 10 | E16: =COUNTIFS(Resources!$D:$D,"communities",Resources!$F:$F,"*Tech Law*") -> 8 | F16: =COUNTIFS(Resources!$D:$D,"communities",Resources!$F:$F,"*General*") -> 0 | G16: =COUNTIF(Resources!$D:$D,"communities") -> 21
A17: Job Boards & Careers | B17: =COUNTIFS(Resources!$D:$D,"jobs",Resources!$F:$F,"*Cybersecurity*") -> 18 | C17: =COUNTIFS(Resources!$D:$D,"jobs",Resources!$F:$F,"*Privacy*") -> 5 | D17: =COUNTIFS(Resources!$D:$D,"jobs",Resources!$F:$F,"*AI*") -> 2 | E17: =COUNTIFS(Resources!$D:$D,"jobs",Resources!$F:$F,"*Tech Law*") -> 1 | F17: =COUNTIFS(Resources!$D:$D,"jobs",Resources!$F:$F,"*General*") -> 2 | G17: =COUNTIF(Resources!$D:$D,"jobs") -> 21
A18: All sections | B18: =SUM(B5:B17) -> 181 | C18: =SUM(C5:C17) -> 157 | D18: =SUM(D5:D17) -> 126 | E18: =SUM(E5:E17) -> 91 | F18: =SUM(F5:F17) -> 23 | G18: =SUM(G5:G17) -> 353

Sheet Removed
A1: Name | B1: Old Section | C1: Reason | D1: Replaced By
A2: Notion | B2: Tools | C2: General productivity software, not specific to cyber, privacy, AI or tech law. | D2: Tools & Templates section
A3: Google Drive | B3: Tools | C3: General productivity software, not specific to cyber, privacy, AI or tech law. | D3: Tools & Templates section
A4: Google Sheets | B4: Tools | C4: General productivity software, not specific to cyber, privacy, AI or tech law. | D4: Tools & Templates section
A5: Google Calendar | B5: Tools | C5: General productivity software, not specific to cyber, privacy, AI or tech law. | D5: Tools & Templates section
A6: Google Keep | B6: Tools | C6: General productivity software, not specific to cyber, privacy, AI or tech law. | D6: Tools & Templates section
A7: Trello | B7: Tools | C7: General productivity software, not specific to cyber, privacy, AI or tech law. | D7: Tools & Templates section
A8: Slack | B8: Tools | C8: General productivity software, not specific to cyber, privacy, AI or tech law. | D8: Tools & Templates section
A9: Lucidchart | B9: Tools | C9: General productivity software, not specific to cyber, privacy, AI or tech law. | D9: Tools & Templates section
A10: Figma | B10: Tools | C10: General productivity software, not specific to cyber, privacy, AI or tech law. | D10: Tools & Templates section
A11: Slidesgo | B11: Tools | C11: General productivity software, not specific to cyber, privacy, AI or tech law. | D11: Tools & Templates section
A12: Genially | B12: Tools | C12: General productivity software, not specific to cyber, privacy, AI or tech law. | D12: Tools & Templates section
... A17: Forest | B17: Tools | C17: General productivity software, not specific to cyber, privacy, AI or tech law. | D17: Tools & Templates section
A18: TED-Ed | B18: Learning Center | C18: General education, no specific relevance.
A19: TED | B19: Learning Center | C19: General talks, no specific relevance.
A20: OER Commons | B20: Learning Center | C20: General open courseware.
A21: OpenStax | B21: Learning Center | C21: General open textbooks.
A22: Skillshare | B22: Learning Center | C22: Creative and business courses, little in these fields.
A23: Google Arts & Culture | B23: Learning Center | C23: Off-topic.
A24: Reflection Toolkit | B24: Learning Center | C24: No link and unclear relevance.
A25: Yale Online | B25: Learning Center | C25: No cyber, privacy, AI or tech-law courses found.
A26: PubMed | B26: Research | C26: Biomedical literature, off-topic. | D26: Google Scholar, SSRN, arXiv
A27: Google Public Data Explorer | B27: Research | C27: General statistics, off-topic.
A28: Eurostat | B28: Research | C28: General EU statistics, off-topic. | D28: data.europa.eu, EUR-Lex
A29: National Renewable Energy Laboratory Research | B29: Research | C29: Energy research, off-topic.
A30: Goodreads | B30: Books & Literature | C30: General book tracker.
A31: Privacy Books (list page) | B31: Books & Literature | C31: Repeated about 25 titles three times, used a third party's Amazon affiliate links, and included titles and authors that could not be matched to real books. | D31: 31 individual book and article entries
A32: Cybersecurity Books (list page) | B32: Books & Literature | C32: List page with no verified entries. | D32: Individual book entries
A33: NinjaJobs | B33: Job Boards | C33: Site now redirects to a recruiting firm with no job listings.
A34: ISEC Jobs | B34: Job Boards | C34: Site shut down on June 30, 2026.
A35: The Tech Law Hangout | B35: Podcasts | C35: No episodes since September 2024; mostly IP and corporate law. | D35: Scaling Laws, Lawfare Daily
A36: BSidesNYC Conference (Oct 2024) | B36: Events | C36: Past event. The 2026 edition is also over and 2027 dates are not announced. | D36: Re-add when dates are published
A37: Hack The Railroad 2024 | B37: Events | C37: Past event; next edition not found.
A38: Innovative Cybersecurity Summit – Scottsdale 2024 | B38: Events | C38: Past event; next edition not found.
A39: The Data Security and Privacy Summit | B39: Events | C39: No date listed; next edition not found.
A40: Data Privacy Conference (Sep 2024) | B40: Events | C40: Past event; next edition not found.
A41: Compliance Week (Feb 2025) | B41: Events | C41: Past event. The organizer lists only the May 2026 edition so far. | D41: Re-add when 2027 dates are published
A42: CAMLIS Conference (Oct 2024) | B42: Events | C42: Past event. The 2026 edition is over and 2027 dates are not announced. | D42: Re-add when dates are published
A43: Cyber Security Training at SANS Network Security (Sep 2024) | B43: Events | C43: Past event. | D43: SANS Network Security 2027
A44: DEF CON 32 (Aug 2024) | B44: Events | C44: Past event. | D44: DEF CON 35
...
